Traceback (most recent call last):
  File "C:\Users\ISNITA\AppData\Local\Programs\Python\Python310\lib\site-packages\jupyter_cache\executors\utils.py", line 58, in single_nb_execution
    executenb(
  File "C:\Users\ISNITA\AppData\Local\Programs\Python\Python310\lib\site-packages\nbclient\client.py", line 1314, in execute
    return NotebookClient(nb=nb, resources=resources, km=km, **kwargs).execute()
  File "C:\Users\ISNITA\AppData\Roaming\Python\Python310\site-packages\jupyter_core\utils\__init__.py", line 166, in wrapped
    return loop.run_until_complete(inner)
  File "C:\Users\ISNITA\AppData\Local\Programs\Python\Python310\lib\asyncio\base_events.py", line 646, in run_until_complete
    return future.result()
  File "C:\Users\ISNITA\AppData\Local\Programs\Python\Python310\lib\site-packages\nbclient\client.py", line 709, in async_execute
    await self.async_execute_cell(
  File "C:\Users\ISNITA\AppData\Local\Programs\Python\Python310\lib\site-packages\nbclient\client.py", line 1062, in async_execute_cell
    await self._check_raise_for_error(cell, cell_index, exec_reply)
  File "C:\Users\ISNITA\AppData\Local\Programs\Python\Python310\lib\site-packages\nbclient\client.py", line 918, in _check_raise_for_error
    raise CellExecutionError.from_cell_and_msg(cell, exec_reply_content)
nbclient.exceptions.CellExecutionError: An error occurred while executing the following cell:
------------------
import numpy as np
import pandas as pd
import requests
import re

from urllib.request import urlopen
from bs4 import BeautifulSoup

from tqdm import tqdm

import nltk
nltk.download('stopwords')
nltk.download('wordnet')
nltk.download('punkt')
from nltk.corpus import stopwords
from Sastrawi.Stemmer.StemmerFactory import StemmerFactory

from sklearn.feature_extraction.text import CountVectorizer
from sklearn.feature_extraction.text import TfidfVectorizer

from sklearn import preprocessing
from sklearn.model_selection import train_test_split
from sklearn.linear_model import LogisticRegression

from sklearn.metrics import accuracy_score, confusion_matrix, classification_report

import seaborn as sns
import matplotlib.pyplot as plt

import pickle
------------------

----- stderr -----
[nltk_data] Downloading package stopwords to
[nltk_data]     C:\Users\ISNITA\AppData\Roaming\nltk_data...
[nltk_data]   Package stopwords is already up-to-date!
[nltk_data] Downloading package wordnet to
[nltk_data]     C:\Users\ISNITA\AppData\Roaming\nltk_data...
[nltk_data]   Package wordnet is already up-to-date!
[nltk_data] Downloading package punkt to
[nltk_data]     C:\Users\ISNITA\AppData\Roaming\nltk_data...
[nltk_data]   Package punkt is already up-to-date!
------------------

[1;31m---------------------------------------------------------------------------[0m
[1;31mModuleNotFoundError[0m                       Traceback (most recent call last)
Cell [1;32mIn[2], line 27[0m
[0;32m     23[0m [38;5;28;01mfrom[39;00m [38;5;21;01msklearn[39;00m[38;5;21;01m.[39;00m[38;5;21;01mlinear_model[39;00m [38;5;28;01mimport[39;00m LogisticRegression
[0;32m     25[0m [38;5;28;01mfrom[39;00m [38;5;21;01msklearn[39;00m[38;5;21;01m.[39;00m[38;5;21;01mmetrics[39;00m [38;5;28;01mimport[39;00m accuracy_score, confusion_matrix, classification_report
[1;32m---> 27[0m [38;5;28;01mimport[39;00m [38;5;21;01mseaborn[39;00m [38;5;28;01mas[39;00m [38;5;21;01msns[39;00m
[0;32m     28[0m [38;5;28;01mimport[39;00m [38;5;21;01mmatplotlib[39;00m[38;5;21;01m.[39;00m[38;5;21;01mpyplot[39;00m [38;5;28;01mas[39;00m [38;5;21;01mplt[39;00m
[0;32m     30[0m [38;5;28;01mimport[39;00m [38;5;21;01mpickle[39;00m

[1;31mModuleNotFoundError[0m: No module named 'seaborn'

